<?xml version="1.0" encoding="utf-8"?>
<!--Aqui comienza el robot-->
<robot name="robot_scara" xmlns:xacro="http://ros.org/wiki/xacro" >

    <link name="world">
    </link>

    <joint name="world_joint" type="fixed">
        <parent link="world"/>
        <child link="base_link"/>
        <origin xyz="0 0 0" rpy="0 0 0"/>
    </joint>


    <link name="base_link">
        <visual>
            <origin xyz="0.0 0.0 0.1" rpy="0 0 0" />
            <geometry>
                <box size="0.1 0.15 0.2" />
            </geometry>
            <material name="grey">
                <color rgba="0.1 0.1 0.1 1.0" />
            </material>
        </visual>
        <collision>
            <origin xyz="0.0 0.0 0.1" rpy="0 0 0" />
            <geometry>
                <box size="0.1 0.15 0.2" />
            </geometry>
        </collision>
        <inertial>
            <origin xyz="0 0 0" rpy="0 0 0"/>
            <mass value="1"/>
            <inertia ixx="1.0" ixy="0.0" ixz="0.0" 
                iyy="1.0" iyz="0.0" izz="1.0"/>
        </inertial>
    </link>

    <link name="link_1">
        <visual>
            <origin xyz="0.25 0.0 0.0" rpy="0 0 0" />
            <geometry>
                <box size="0.5 0.05 0.05" />
            </geometry>
            <material name="red">
                <color rgba="1 0.0 0.0 1.0"/>
            </material>
        </visual>
        <collision>
            <origin xyz="0.25 0.0 0.0" rpy="0 0 0" />
            <geometry>
                <box size="0.5 0.05 0.05" />
            </geometry>
        </collision>
        <inertial>
            <origin xyz="0 0 0" rpy="0 0 0"/>
            <mass value="1"/>
            <inertia ixx="1.0" ixy="0.0" ixz="0.0" 
                iyy="1.0" iyz="0.0" izz="1.0"/>
        </inertial>
    </link>

    <joint name="link_1_joint" type="revolute">
        <parent link="base_link"/>
        <child link="link_1"/>
        <axis xyz="0 0 1"/>
        <limit lower="-3.14159" upper="3.14159" velocity="50.0" 
               effort="1000.0"/>
        <origin xyz="0 0 0.225" rpy="0 0 0"/>
    </joint>

    <link name="link_2">
        <visual>
            <origin xyz="0.25 0.0 0.0" rpy="0 0 0" />
            <geometry>
                <box size="0.5 0.05 0.05" />
            </geometry>
            <material name="green">
                <color rgba="0.0 1.0 0.0 1.0" />
            </material>
        </visual>
        <collision>
            <origin xyz="0.25 0.0 0.0" rpy="0 0 0" />
            <geometry>
                <box size="0.5 0.05 0.05" />
            </geometry>
        </collision>
        <inertial>
            <origin xyz="0 0 0" rpy="0 0 0"/>
            <mass value="1"/>
            <inertia ixx="1.0" ixy="0.0" ixz="0.0" 
                iyy="1.0" iyz="0.0" izz="1.0"/>
        </inertial>
    </link>

    <joint name="link_2_joint" type="revolute">
        <parent link="link_1"/>
        <child link="link_2"/>
        <axis xyz="0 0 1"/>
        <limit lower="-3.14159" upper="3.14159" velocity="50.0" 
               effort="1000.0"/>
        <origin xyz="0.45 0 0.05" rpy="0 0 0"/>
    </joint>

    <link name="link_3">
        <visual>
            <origin xyz="0.15 0.0 0.0" rpy="0 0 0" />
            <geometry>
                <box size="0.3 0.05 0.05" />
            </geometry>
            <material name="blue">
                <color rgba="0.0 0.0 1.0 1.0" />
            </material>
        </visual>
        <collision>
            <origin xyz="0.15 0.0 0.0" rpy="0 0 0" />
            <geometry>
                <box size="0.3 0.05 0.05" />
            </geometry>
        </collision>
        <inertial>
            <origin xyz="0 0 0" rpy="0 0 0"/>
            <mass value="1"/>
            <inertia ixx="1.0" ixy="0.0" ixz="0.0" 
                iyy="1.0" iyz="0.0" izz="1.0"/>
        </inertial>
    </link>

    <joint name="link_3_joint" type="revolute">
        <parent link="link_2"/>
        <child link="link_3"/>
        <axis xyz="0 0 1"/>
        <limit lower="-3.14159" upper="3.14159" velocity="50.0" 
               effort="1000.0"/>
        <origin xyz="0.45 0 -0.05" rpy="0 0 0"/>
    </joint>
    
    <link name="link_4">
        <visual>
            <origin xyz="0.0 0.0 0.0" rpy="0 0 0"/>
            <geometry>
              <box size="0.1 0.05 0.2"/>
            </geometry>
            <material name="yellow">
              <color rgba="1.0 1.0 0.0 1.0"/>
            </material>
        </visual>
        <collision>
            <origin xyz="0.0 0.0 0.0" rpy="0 0 0"/>
            <geometry>
              <box size="0.1 0.05 0.2"/>
            </geometry>
        </collision>
        <inertial>
            <origin xyz="0 0 0" rpy="0 0 0"/>
            <mass value="1"/>
            <inertia ixx="1.0" ixy="0.0" ixz="0.0" iyy="1.0" iyz="0.0" izz="1.0"/>
         </inertial>
    </link>

    <joint name="link_4_joint" type="prismatic">
         <parent link="link_1"/>
         <child  link="link_4"/>
         <origin xyz="0.5 0 0" rpy="0 0 0"/>
         <!-- se desliza a lo largo de Z -->
         <axis xyz="0 0 1"/>
         <!-- límites en metros -->
         <limit lower="0.0" upper="0.1" effort="100.0" velocity="0.2"/>  
    </joint>

    <link name="P">
    </link>

    <joint name="link_P_joint" type="fixed">
        <parent link="link_3"/>
        <child link="P"/>
        <origin xyz="0.25 0 0" rpy="0 0 0"/>
    </joint>
        <!-- LIDAR LINK -->
    <link name="lidar_link">
      <visual>
        <origin xyz="0 0 0.15" rpy="0 0 0"/>
        <geometry>
          <cylinder radius="0.03" length="0.05"/>
        </geometry>
        <material name="lidar_black">
          <color rgba="0.0 0.0 0.0 1.0"/>
        </material>
      </visual>
      <collision>
        <origin xyz="0 0 0.15" rpy="0 0 0"/>
        <geometry>
          <cylinder radius="0.03" length="0.05"/>
        </geometry>
      </collision>
      <inertial>
        <origin xyz="0 0 0" rpy="0 0 0"/>
        <mass value="0.2"/>
        <inertia ixx="1e-3" ixy="0.0" ixz="0.0" iyy="1e-3" iyz="0.0" izz="1e-3"/>
      </inertial>
    </link>

    <joint name="lidar_joint" type="fixed">
      <parent link="base_link"/>
      <child link="lidar_link"/>
      <!-- colocamos el lidar encima de la base -->
      <origin xyz="0 0 0.25" rpy="0 0 0"/>
    </joint>


    <!-- Sensor LiDAR en Gazebo, asociado a lidar_link -->
    <gazebo reference="lidar_link">
      <sensor name="lidar" type="ray">
        <always_on>true</always_on>
        <update_rate>10</update_rate>
        <visualize>true</visualize>

        <pose>0 0 0 0 0 0</pose>

        <ray>
          <scan>
            <horizontal>
              <samples>360</samples>
              <resolution>1</resolution>
              <min_angle>-3.14159</min_angle>
              <max_angle>3.14159</max_angle>
            </horizontal>
          </scan>
          <range>
            <min>0.1</min>
            <max>5.0</max>
            <resolution>0.01</resolution>
          </range>
        </ray>

        <!-- nombre del tópico DENTRO de Gazebo -->
        <topic>/lidar</topic>
      </sensor>
    </gazebo>
  </robot>


</robot>
