<?xml version="1.0" ?>
<!-- =================================================================================== -->
<!-- |    This document was autogenerated by xacro from scara_urdf.xacro               | -->
<!-- |    EDITING THIS FILE BY HAND IS NOT RECOMMENDED                                 | -->
<!-- =================================================================================== -->
<!--Aqui comienza el robot-->
<robot name="robot_scara">
  <link name="world">
    </link>
  <joint name="world_joint" type="fixed">
    <parent link="world"/>
    <child link="base_link"/>
    <origin rpy="0 0 0" xyz="0 0 0"/>
  </joint>
  <link name="base_link">
    <visual>
      <origin rpy="0 0 0" xyz="0.0 0.0 0.1"/>
      <geometry>
        <box size="0.1 0.15 0.2"/>
      </geometry>
      <material name="grey">
        <color rgba="0.1 0.1 0.1 1.0"/>
      </material>
    </visual>
    <collision>
      <origin rpy="0 0 0" xyz="0.0 0.0 0.1"/>
      <geometry>
        <box size="0.1 0.15 0.2"/>
      </geometry>
    </collision>
    <inertial>
      <origin rpy="0 0 0" xyz="0 0 0"/>
      <mass value="1"/>
      <inertia ixx="1.0" ixy="0.0" ixz="0.0" iyy="1.0" iyz="0.0" izz="1.0"/>
    </inertial>
  </link>
  <link name="link_1">
    <visual>
      <origin rpy="0 0 0" xyz="0.25 0.0 0.0"/>
      <geometry>
        <box size="0.5 0.05 0.05"/>
      </geometry>
      <material name="red">
        <color rgba="1 0.0 0.0 1.0"/>
      </material>
    </visual>
    <collision>
      <origin rpy="0 0 0" xyz="0.25 0.0 0.0"/>
      <geometry>
        <box size="0.5 0.05 0.05"/>
      </geometry>
    </collision>
    <inertial>
      <origin rpy="0 0 0" xyz="0 0 0"/>
      <mass value="1"/>
      <inertia ixx="1.0" ixy="0.0" ixz="0.0" iyy="1.0" iyz="0.0" izz="1.0"/>
    </inertial>
  </link>
  <joint name="link_1_joint" type="revolute">
    <parent link="base_link"/>
    <child link="link_1"/>
    <axis xyz="0 0 1"/>
    <limit effort="1000.0" lower="-3.14159" upper="3.14159" velocity="50.0"/>
    <origin rpy="0 0 0" xyz="0 0 0.225"/>
  </joint>
  <link name="link_2">
    <visual>
      <origin rpy="0 0 0" xyz="0.25 0.0 0.0"/>
      <geometry>
        <box size="0.5 0.05 0.05"/>
      </geometry>
      <material name="green">
        <color rgba="0.0 1.0 0.0 1.0"/>
      </material>
    </visual>
    <collision>
      <origin rpy="0 0 0" xyz="0.25 0.0 0.0"/>
      <geometry>
        <box size="0.5 0.05 0.05"/>
      </geometry>
    </collision>
    <inertial>
      <origin rpy="0 0 0" xyz="0 0 0"/>
      <mass value="1"/>
      <inertia ixx="1.0" ixy="0.0" ixz="0.0" iyy="1.0" iyz="0.0" izz="1.0"/>
    </inertial>
  </link>
  <joint name="link_2_joint" type="revolute">
    <parent link="link_1"/>
    <child link="link_2"/>
    <axis xyz="0 0 1"/>
    <limit effort="1000.0" lower="-3.14159" upper="3.14159" velocity="50.0"/>
    <origin rpy="0 0 0" xyz="0.45 0 0.05"/>
  </joint>
  <link name="link_3">
    <visual>
      <origin rpy="0 0 0" xyz="0.15 0.0 0.0"/>
      <geometry>
        <box size="0.3 0.05 0.05"/>
      </geometry>
      <material name="blue">
        <color rgba="0.0 0.0 1.0 1.0"/>
      </material>
    </visual>
    <collision>
      <origin rpy="0 0 0" xyz="0.15 0.0 0.0"/>
      <geometry>
        <box size="0.3 0.05 0.05"/>
      </geometry>
    </collision>
    <inertial>
      <origin rpy="0 0 0" xyz="0 0 0"/>
      <mass value="1"/>
      <inertia ixx="1.0" ixy="0.0" ixz="0.0" iyy="1.0" iyz="0.0" izz="1.0"/>
    </inertial>
  </link>
  <joint name="link_3_joint" type="revolute">
    <parent link="link_2"/>
    <child link="link_3"/>
    <axis xyz="0 0 1"/>
    <limit effort="1000.0" lower="-3.14159" upper="3.14159" velocity="50.0"/>
    <origin rpy="0 0 0" xyz="0.45 0 -0.05"/>
  </joint>
  <link name="link_4">
    <visual>
      <origin rpy="0 0 0" xyz="0.0 0.0 0.0"/>
      <geometry>
        <box size="0.1 0.05 0.2"/>
      </geometry>
      <material name="yellow">
        <color rgba="1.0 1.0 0.0 1.0"/>
      </material>
    </visual>
    <collision>
      <origin rpy="0 0 0" xyz="0.0 0.0 0.0"/>
      <geometry>
        <box size="0.1 0.05 0.2"/>
      </geometry>
    </collision>
    <inertial>
      <origin rpy="0 0 0" xyz="0 0 0"/>
      <mass value="1"/>
      <inertia ixx="1.0" ixy="0.0" ixz="0.0" iyy="1.0" iyz="0.0" izz="1.0"/>
    </inertial>
  </link>
  <joint name="link_4_joint" type="prismatic">
    <parent link="link_1"/>
    <child link="link_4"/>
    <origin rpy="0 0 0" xyz="0.5 0 0"/>
    <!-- se desliza a lo largo de Z -->
    <axis xyz="0 0 1"/>
    <!-- límites en metros -->
    <limit effort="100.0" lower="0.0" upper="0.1" velocity="0.2"/>
  </joint>
  <link name="P">
    </link>
  <joint name="link_P_joint" type="fixed">
    <parent link="link_3"/>
    <child link="P"/>
    <origin rpy="0 0 0" xyz="0.25 0 0"/>
  </joint>
</robot>
